Workbook

Sheet Leia-me
A1: Lista A: reativação de distribuidoras do Sudeste
A2: Fonte: Sankhya, extraído em 27/10/2026. Faturamento bruto dos últimos 24 meses, sem devoluções.
A4: Resumo
A5: Distribuidoras / atacadistas | B5: =COUNTA(Distribuidoras!B2:B41) -> 40
A6: prioridade A (≥ R$ 20 mil) | B6: =COUNTIF(Distribuidoras!A2:A41,"A") -> 13
A7: faturamento 24m em jogo (R$) | B7: =SUM(Distribuidoras!O2:O41) -> 1277662
A8: sem vendedor (SDR liga direto) | B8: =COUNTIF(Distribuidoras!J2:J41,"SDR*") -> 11
A9: Lojas em tabela atacado | B9: =COUNTA('Lojas em tabela atacado'!B2:B15) -> 14
A10: faturamento 24m em jogo (R$) | B10: =SUM('Lojas em tabela atacado'!O2:O15) -> 687518
A11: Key accounts parados (gestor) | B11: =COUNTA('Key accounts (gestor)'!A2:A9) -> 8
A12: faturamento 24m em jogo (R$) | B12: =SUM('Key accounts (gestor)'!I2:I9) -> 5660106
A13: Pedidos fechados até agora | B13: =COUNTIF(Distribuidoras!T2:T41,"Pedido fechado")+COUNTIF('Lojas em tabela atacado'!T2:T15,"Pedido fechado") -> 0
A14: Valor reativado (R$) | B14: =SUM(Distribuidoras!Y2:Y41)+SUM('Lojas em tabela atacado'!Y2:Y15) -> 0
A16: Quem entrou
A17: Região | B17: SP, RJ, MG e ES.
A18: Critério | B18: Nome com DISTRIBUIDORA/ATACADISTA ou tabela de preço de distribuidor/atacado (o Sankhya não tem campo de segmento, então a lista é aproximada).
A19: Parado | B19: O grupo inteiro (todas as filiais) está há 60+ dias sem comprar e comprou pelo menos R$ 1.500 nos últimos 24 meses. Filial parada de grupo que segue comprando não entra.
A20: Prioridade | B20: A = comprou R$ 20 mil ou mais em 24 meses · B = R$ 5–20 mil · C = abaixo de R$ 5 mil.
A22: Como usar
A23: Abas | B23: Distribuidoras: lista principal da prospecção. Lojas em tabela atacado: varejistas que compram em tabela de atacado, prioridade menor. Key accounts: NÃO ligar, o gestor da conta trata. Fora da lista: o que foi tirado e por quê.
A24: Quem liga | B24: 'SDR (sem dono)': o cliente não tem vendedor na carteira, o time liga direto. 'Vendedor (alinhar antes)': falar com o vendedor antes de ligar, para não atravessar a carteira dele.
A25: Colunas amarelas | B25: São para o time preencher (Status, Data do contato, Responsável, Motivo da parada, Próximo passo, Valor do pedido). Status tem lista suspensa. O resumo acima atualiza sozinho.
A26: Exemplo de preenchimento | B26: Status = Em conversa · Data = 03/11/2026 · Responsável = Ana · Motivo = Achou o frete CIF caro · Próximo passo = Enviar proposta FOB até 05/11 · Valor = (só quando fechar).
A27: Telefone e e-mail | B27: A visão do Sankhya usada aqui não traz contato. Pegar no cadastro do ERP pelo CNPJ ou na consulta pública de CNPJ.
A29: Roteiro da ligação
A30: 1. Abertura | B30: "Oi, aqui é [nome] da Nitron. Vocês compravam a nossa [linha que mais comprava] até [mês da última compra] e eu queria entender o que mudou."
A31: 2. Diagnóstico | B31: Por que parou? Preço, frete, prazo, ruptura, atendimento, trocou de fornecedor, o produto não girou? Anotar em 'Motivo da parada'.
A32: 3. Oferta | B32: Responder ao motivo: tabela de distribuidor, pedido mínimo CIF da região, lançamentos da linha que ele já comprava, prazo.
A33: 4. Fechamento | B33: Sair com um pedido ou com data marcada. Nunca terminar a ligação sem um próximo passo.

Sheet Distribuidoras
A1: Prioridade | B1: Razão social | C1: Nome fantasia | D1: CNPJ | E1: Cidade | F1: UF | G1: Lojas/CNPJs | H1: Vendedor da carteira | I1: Gestor | J1: Quem liga | K1: Tabela de preço | L1: 1ª compra | M1: Última compra | N1: Dias sem compra | O1: Faturamento 24m (R$) | P1: Notas 24m | Q1: Ticket médio (R$) | R1: Linhas que mais comprava | S1: Observação | T1: Status | U1: Data do contato | V1: Responsável | W1: Motivo da parada | X1: Próximo passo | Y1: Valor do pedido (R$)
A2: =IF(O2>=20000,"A",IF(O2>=5000,"B","C")) -> A | B2: ARMAZEM DO BASICO LTDA | C2: ARMAZEM DO BASICO | D2: 39.240.706/0001-66 | E2: Jundiaí | F2: SP | G2: 1 | H2: VALERIA | I2: MARCOS | J2: Vendedor (alinhar antes) | K2: CLUBE NITRON ATACADO COMISSÃO 6% | L2: 45608 | M2: 46218 | N2: =TODAY()-M2 -> 104 | O2: 526691 | P2: 51 | Q2: =IF(P2>0,O2/P2,0) -> 10327.275 | R2: Organização 41% | Potes 28% | Frasqueiras 23% | S2: Maior da lista: ~R$ 26 mil/mês até jul/26. Prioridade máxima. | T2: A contatar
A3: =IF(O3>=20000,"A",IF(O3>=5000,"B","C")) -> A | B3: SENSITIVE DISTRIBUIDORA LTDA | C3: SENSITIVE DISTRIBUIDORA | D3: 33.150.867/0001-82 | E3: São Paulo | F3: SP | G3: 1 | H3: VALERIA | I3: Coord. Int | J3: Vendedor (alinhar antes) | K3: TABELA 30% OFF | L3: 45776 | M3: 46162 | N3: =TODAY()-M3 -> 160 | O3: 87408 | P3: 19 | Q3: =IF(P3>0,O3/P3,0) -> 4600.4211 | R3: Frasqueiras 100% | S3: Só compra frasqueiras: perfil distribuidor de cosméticos/higiene. | T3: A contatar
A4: =IF(O4>=20000,"A",IF(O4>=5000,"B","C")) -> A | B4: NETFACIL DISTRIBUIDORA DE PRODUTOS EM GERAL LTDA | C4: NETFACIL / M75 | D4: 51.845.015/0001-91 | E4: São Paulo | F4: SP | G4: 2 | H4: <SEM VENDEDOR> | I4: Coord. Int | J4: SDR (sem dono) | K4: PV0003 - TABELA PADRÃO | L4: 45595 | M4: 46168 | N4: =TODAY()-M4 -> 154 | O4: 67004 | P4: 27 | Q4: =IF(P4>0,O4/P4,0) -> 2481.6296 | R4: Frasqueiras 67% | Cozinha 25% | Organização 8% | S4: Grupo NetFácil + M75 (2 CNPJs). Sem vendedor na carteira. | T4: A contatar
A5: =IF(O5>=20000,"A",IF(O5>=5000,"B","C")) -> A | B5: JMP ATACADISTA DE ALIMENTOS LTDA | C5: JMP ATACADISTA | D5: 57.469.217/0001-62 | E5: Serra | F5: ES | G5: 4 | H5: LUCIANE VOGEL | I5: Sudeste | J5: Vendedor (alinhar antes) | K5: PV0003 - TABELA PADRÃO | L5: 45609 | M5: 45952 | N5: =TODAY()-M5 -> 370 | O5: 65849 | P5: 11 | Q5: =IF(P5>0,O5/P5,0) -> 5986.2727 | R5: Lixeiras 35% | Cozinha 19% | Banheiro 15% | S5: Atacadista de alimentos com 4 lojas: oferecer mix de giro (lixeiras, cozinha). | T5: A contatar
A6: =IF(O6>=20000,"A",IF(O6>=5000,"B","C")) -> A | B6: USATEST TECH IMPORT LTDA | C6: USATEST TECH IMPORT | D6: 32.076.437/0001-03 | E6: Atibaia | F6: SP | G6: 2 | H6: MILTON | I6: Int e Vale | J6: Vendedor (alinhar antes) | K6: CLUBE NITRON DISTR. COMISSÃO 4% | L6: 45665 | M6: 46098 | N6: =TODAY()-M6 -> 224 | O6: 56349 | P6: 6 | Q6: =IF(P6>0,O6/P6,0) -> 9391.5 | R6: Frasqueiras 100% | S6: Só frasqueiras. | T6: A contatar
A7: =IF(O7>=20000,"A",IF(O7>=5000,"B","C")) -> A | B7: CDBU DISTRIBUIDORA DE BRINQUEDOS E UTILI | C7: CAMICADO LJ1 (conferir cadastro) | D7: 52.564.614/0001-08 | E7: São Paulo | F7: SP | G7: 1 | H7: MILTON | I7: Capital SP | J7: Vendedor (alinhar antes) | K7: PV0003 - TABELA PADRÃO | L7: 45615 | M7: 46245 | N7: =TODAY()-M7 -> 77 | O7: 55014 | P7: 14 | Q7: =IF(P7>0,O7/P7,0) -> 3929.5714 | R7: Potes 36% | Organização 34% | Cozinha 15% | S7: Razão é CDBU, fantasia no cadastro diz Camicado: confirmar com quem fala. | T7: A contatar
A8: =IF(O8>=20000,"A",IF(O8>=5000,"B","C")) -> A | B8: COMERCIAL LEONEL & MEDEIROS EIRELI | C8: LEONEL & MEDEIROS | D8: 03.668.525/0001-98 | E8: Uberlândia | F8: MG | G8: 1 | H8: GERALDO | I8: Sudeste | J8: Vendedor (alinhar antes) | K8: CLUBE NITRON RED 155 ATACAD. COMISSÃO 6% | L8: 45632 | M8: 46202 | N8: =TODAY()-M8 -> 120 | O8: 53916 | P8: 5 | Q8: =IF(P8>0,O8/P8,0) -> 10783.2 | R8: Organização 23% | Lixeiras 23% | Cozinha 17% | T8: A contatar
A9: =IF(O9>=20000,"A",IF(O9>=5000,"B","C")) -> A | B9: PROTTE ATACADO LTDA | C9: PROTTE ATACADO | D9: 64.263.255/0001-20 | E9: Belo Horizonte | F9: MG | G9: 2 | H9: GERALDO | I9: Sudeste | J9: Vendedor (alinhar antes) | K9: CLUBE NITRON ATACADO COMISSÃO 6% | L9: 45786 | M9: 46224 | N9: =TODAY()-M9 -> 98 | O9: 48349 | P9: 4 | Q9: =IF(P9>0,O9/P9,0) -> 12087.25 | R9: Potes 24% | Cozinha 19% | Lixeiras 15% | T9: A contatar
A10: =IF(O10>=20000,"A",IF(O10>=5000,"B","C")) -> A | B10: F. F. ATACADISTA SAO CARLOS LTDA | C10: F. F. ATACADISTA / UNISHOP | D10: 20.182.582/0001-81 | E10: São Carlos | F10: SP | G10: 3 | H10: AUTO ATEND. | I10: Coord. Int | J10: SDR (sem dono) | K10: PV0003 - TABELA PADRÃO | L10: 45607 | M10: 46086 | N10: =TODAY()-M10 -> 236 | O10: 40555 | P10: 7 | Q10: =IF(P10>0,O10/P10,0) -> 5793.5714 | R10: Organização 35% | Lixeiras 27% | Cozinha 14% | S10: Grupo de 3 CNPJs (inclui Unishop/SK). Sem vendedor. | T10: A contatar
A11: =IF(O11>=20000,"A",IF(O11>=5000,"B","C")) -> A | B11: F R W DISTRIBUIDORA E COMERCIO LTDA | C11: BAFAFA | D11: 54.560.250/0001-05 | E11: Cachoeiro de Itapemirim | F11: ES | G11: 1 | H11: JOANA | I11: Sudeste | J11: Vendedor (alinhar antes) | K11: PV0003 - TABELA PADRÃO | L11: 45612 | M11: 45957 | N11: =TODAY()-M11 -> 365 | O11: 29572 | P11: 3 | Q11: =IF(P11>0,O11/P11,0) -> 9857.3333 | R11: Organização 42% | Cozinha 12% | Lixeiras 9% | T11: A contatar
A12: =IF(O12>=20000,"A",IF(O12>=5000,"B","C")) -> A | B12: S.A.L INDUSTRIA E COMERCIO DE UTILIDADES | C12: S.A.L UTILIDADES | D12: 26.172.371/0001-44 | E12: Contagem | F12: MG | G12: 1 | H12: FIGUEROA | I12: Sudeste | J12: Vendedor (alinhar antes) | K12: CLUBE NITRON ATACADO COMISSÃO 6% | L12: 45636 | M12: 46008 | N12: =TODAY()-M12 -> 314 | O12: 28760 | P12: 5 | Q12: =IF(P12>0,O12/P12,0) -> 5752 | R12: Potes 30% | Organização 17% | Jarras 14% | T12: A contatar
A13: =IF(O13>=20000,"A",IF(O13>=5000,"B","C")) -> A | B13: DISTRIBUIDORA TRANSPORTADORA ARMAZENAMENTO & EMPREENDIMENTOS | C13: DISTRIB. TRANSP. ARMAZENAMENTO | D13: 64.764.997/0001-39 | E13: Inimutaba | F13: MG | G13: 1 | H13: DENIZE | I13: Sudeste | J13: Vendedor (alinhar antes) | K13: TABELA ESPECIAL MINAS | L13: 46172 | M13: 46172 | N13: =TODAY()-M13 -> 150 | O13: 25207 | P13: 1 | Q13: =IF(P13>0,O13/P13,0) -> 25207 | R13: Potes 29% | Organização 20% | Cozinha 18% | S13: Comprou 1 vez (R$ 25 mil, mai/26) e não voltou: entender o porquê. | T13: A contatar
A14: =IF(O14>=20000,"A",IF(O14>=5000,"B","C")) -> A | B14: SPF DISTRIBUIDORA DE UTILIDADES DOMESTICAS LTDA | C14: SPF DISTRIBUIDORA | D14: 01.387.543/0001-76 | E14: Santa Bárbara d'Oeste | F14: SP | G14: 1 | H14: HELENA SANTOS S | I14: Int e Vale | J14: Vendedor (alinhar antes) | K14: PV0003 - TABELA PADRÃO | L14: 45596 | M14: 45967 | N14: =TODAY()-M14 -> 355 | O14: 21848 | P14: 8 | Q14: =IF(P14>0,O14/P14,0) -> 2731 | R14: Cozinha 72% | Organização 26% | Banheiro 2% | S14: Comprava basicamente Linha Cozinha. | T14: A contatar
A15: =IF(O15>=20000,"A",IF(O15>=5000,"B","C")) -> B | B15: DISTRIBUIDORA SUDARIO LTDA | C15: CLARA EDUARDA UTILIDADES | D15: 10.692.584/0001-67 | E15: Betim | F15: MG | G15: 1 | H15: EVERTON | I15: Sudeste | J15: Vendedor (alinhar antes) | K15: PV0003 - TABELA PADRÃO | L15: 45630 | M15: 46053 | N15: =TODAY()-M15 -> 269 | O15: 14984 | P15: 5 | Q15: =IF(P15>0,O15/P15,0) -> 2996.8 | R15: Organização 26% | Cozinha 18% | Limpeza 15% | T15: A contatar
A16: =IF(O16>=20000,"A",IF(O16>=5000,"B","C")) -> B | B16: PRADO DISTRIBUIDORA DE UTILIDADE DOMESTICA LTDA | C16: FOGO AZUL SP | D16: 34.647.606/0002-16 | E16: São Paulo | F16: SP | G16: 2 | H16: <SEM VENDEDOR> | I16: Coord. Int | J16: SDR (sem dono) | K16: PV0003 - TABELA PADRÃO | L16: 45681 | M16: 45990 | N16: =TODAY()-M16 -> 332 | O16: 13988 | P16: 5 | Q16: =IF(P16>0,O16/P16,0) -> 2797.6 | R16: Decor-Chef 45% | Decor-Confeitaria 37% | Cozinha 16% | S16: Foco Decor-Chef/Confeitaria. Sem vendedor. | T16: A contatar
A17: =IF(O17>=20000,"A",IF(O17>=5000,"B","C")) -> B | B17: REAL DISTRIBUIDORA DE UTILIDADES LTDA | C17: REAL DISTRIBUIDORA | D17: 63.377.488/0001-90 | E17: São Paulo | F17: SP | G17: 1 | H17: VALERIA | I17: Coord. Int | J17: Vendedor (alinhar antes) | K17: TABELA 30% OFF | L17: 46002 | M17: 46190 | N17: =TODAY()-M17 -> 132 | O17: 12213 | P17: 3 | Q17: =IF(P17>0,O17/P17,0) -> 4071 | R17: Organização 29% | Potes 18% | Lixeiras 15% | T17: A contatar
A18: =IF(O18>=20000,"A",IF(O18>=5000,"B","C")) -> B | B18: JMR DISTRIBUIDORA DE UTENSILIOS LTDA | C18: JMR DISTRIBUIDORA | D18: 59.818.078/0001-60 | E18: São Paulo | F18: SP | G18: 1 | H18: ESTEVANY | I18: Coord. Int | J18: Vendedor (alinhar antes) | K18: PV0003 - TABELA PADRÃO | L18: 45835 | M18: 45854 | N18: =TODAY()-M18 -> 468 | O18: 11922 | P18: 2 | Q18: =IF(P18>0,O18/P18,0) -> 5961 | R18: Organização 21% | Limpeza 9% | Micro-ondas 9% | T18: A contatar
A19: =IF(O19>=20000,"A",IF(O19>=5000,"B","C")) -> B | B19: RECOM COMERCIO E DISTRIBUICAO DE PRODUTO | C19: COMERCIAL RECOM | D19: 27.232.368/0001-31 | E19: Guaçuí | F19: ES | G19: 1 | H19: JOANA | I19: Sudeste | J19: Vendedor (alinhar antes) | K19: PV0003 - TABELA PADRÃO | L19: 45729 | M19: 46000 | N19: =TODAY()-M19 -> 322 | O19: 9863 | P19: 2 | Q19: =IF(P19>0,O19/P19,0) -> 4931.5 | R19: Frasqueiras 91% | Organização 5% | Infantil 2% | S19: Quase só frasqueiras. | T19: A contatar
A20: =IF(O20>=20000,"A",IF(O20>=5000,"B","C")) -> B | B20: VIABILIZA COMERCIAL ATACADISTA LTDA | C20: VIABILIZA ATACADISTA | D20: 53.523.812/0001-88 | E20: Serra | F20: ES | G20: 1 | H20: LUCIANE VOGEL | I20: Sudeste | J20: Vendedor (alinhar antes) | K20: PV0004 - TABELA ESPECIAL RED | L20: 45951 | M20: 45952 | N20: =TODAY()-M20 -> 370 | O20: 9804 | P20: 2 | Q20: =IF(P20>0,O20/P20,0) -> 4902 | R20: Cozinha 45% | Potes 43% | Micro-ondas 13% | T20: A contatar
A21: =IF(O21>=20000,"A",IF(O21>=5000,"B","C")) -> B | B21: REJUVI ATACADISTA LTDA | C21: REJUVI ATACADISTA | D21: 53.824.879/0001-52 | E21: Iracemápolis | F21: SP | G21: 1 | H21: JOSÉ C LEAL | I21: Int e Vale | J21: Vendedor (alinhar antes) | K21: PV0003 - TABELA PADRÃO | L21: 46128 | M21: 46128 | N21: =TODAY()-M21 -> 194 | O21: 9121 | P21: 1 | Q21: =IF(P21>0,O21/P21,0) -> 9121 | R21: Infantil 100% | S21: 1ª compra abr/26, só Linha Infantil. | T21: A contatar
A22: =IF(O22>=20000,"A",IF(O22>=5000,"B","C")) -> B | B22: DISTRIBUIDORA CANABARRO LTDA | C22: DISTRIBUIDORA CANABARRO | D22: 13.447.000/0001-86 | E22: Guarapari | F22: ES | G22: 1 | H22: VALERIA | I22: Coord. Int | J22: Vendedor (alinhar antes) | K22: PV0003 - TABELA PADRÃO | L22: 45621 | M22: 46191 | N22: =TODAY()-M22 -> 131 | O22: 8562 | P22: 4 | Q22: =IF(P22>0,O22/P22,0) -> 2140.5 | R22: Frasqueiras 100% | S22: Só frasqueiras. | T22: A contatar
A23: =IF(O23>=20000,"A",IF(O23>=5000,"B","C")) -> B | B23: STAR DISTRIBUIDORA DE UTILIDADES E BRINQ | C23: STAR DISTRIBUIDORA | D23: 54.734.384/0001-03 | E23: São José do Rio Preto | F23: SP | G23: 1 | H23: AUTO ATEND. | I23: Coord. Int | J23: SDR (sem dono) | K23: PV0003 - TABELA PADRÃO | L23: 45671 | M23: 45799 | N23: =TODAY()-M23 -> 523 | O23: 8177 | P23: 2 | Q23: =IF(P23>0,O23/P23,0) -> 4088.5 | R23: Lixeiras 37% | Cozinha 22% | Potes 17% | T23: A contatar
A24: =IF(O24>=20000,"A",IF(O24>=5000,"B","C")) -> B | B24: QUALIVIDROS DISTRIBUIDORA LTDA | C24: QUALIVIDROS | D24: 06.003.551/0001-95 | E24: Passos | F24: MG | G24: 1 | H24: MARCOS | I24: Sudeste | J24: Vendedor (alinhar antes) | K24: TABELA CIF MG DEMAIS CIDADES | L24: 45838 | M24: 45838 | N24: =TODAY()-M24 -> 484 | O24: 7883 | P24: 1 | Q24: =IF(P24>0,O24/P24,0) -> 7883 | R24: Organização 100% | T24: A contatar
A25: =IF(O25>=20000,"A",IF(O25>=5000,"B","C")) -> B | B25: DISTRIBUIDORA RIBEIRO LTDA | C25: DISTRIBUIDORA RIBEIRO | D25: 53.449.341/0001-05 | E25: São Paulo | F25: SP | G25: 1 | H25: AUTO ATEND. | J25: SDR (sem dono) | K25: PV0003 - TABELA PADRÃO | L25: 45593 | M25: 45593 | N25: =TODAY()-M25 -> 729 | O25: 6105 | P25: 1 | Q25: =IF(P25>0,O25/P25,0) -> 6105 | R25: Organização 80% | Infantil 9% | Banheiro 4% | S25: Cadastro INATIVO no ERP: reativar antes de faturar. | T25: A contatar
A26: =IF(O26>=20000,"A",IF(O26>=5000,"B","C")) -> B | B26: DISTRIBUIDORA DE PAPEIS RAFAEL LTDA - EPP | C26: PAPEIS RAFAEL | D26: 18.371.526/0001-43 | E26: Sete Lagoas | F26: MG | G26: 1 | H26: ANNA CAROLINA | I26: Sudeste | J26: Vendedor (alinhar antes) | K26: PV0003 - TABELA PADRÃO | L26: 45681 | M26: 45681 | N26: =TODAY()-M26 -> 641 | O26: 5989 | P26: 1 | Q26: =IF(P26>0,O26/P26,0) -> 5989 | R26: Lixeiras 30% | Organização 30% | Potes 28% | T26: A contatar
A27: =IF(O27>=20000,"A",IF(O27>=5000,"B","C")) -> B | B27: SACRAMOMENTO ATACADISTA EIRELI | C27: SACRAMOMENTO ATACADISTA | D27: 09.192.407/0001-32 | E27: Contagem | F27: MG | G27: 1 | H27: FIGUEROA | I27: Sudeste | J27: Vendedor (alinhar antes) | K27: PV0003 - TABELA PADRÃO | L27: 46142 | M27: 46142 | N27: =TODAY()-M27 -> 180 | O27: 5934 | P27: 1 | Q27: =IF(P27>0,O27/P27,0) -> 5934 | R27: Organização 27% | Jarras 23% | Lixeiras 14% | T27: A contatar
A28: =IF(O28>=20000,"A",IF(O28>=5000,"B","C")) -> B | B28: ACESSO COMERCIAL, DISTRIBUIDORA E SERVIC | C28: MIX LAR | D28: 28.985.346/0001-05 | E28: São Paulo | F28: SP | G28: 1 | H28: AUTO ATEND. | J28: SDR (sem dono) | K28: PV0003 - TABELA PADRÃO | L28: 45628 | M28: 45772 | N28: =TODAY()-M28 -> 550 | O28: 5423 | P28: 2 | Q28: =IF(P28>0,O28/P28,0) -> 2711.5 | R28: Cozinha 35% | Potes 26% | Limpeza 21% | S28: Cadastro INATIVO no ERP: reativar antes de faturar. | T28: A contatar
A29: =IF(O29>=20000,"A",IF(O29>=5000,"B","C")) -> B | B29: SINERGIA ATACADISTA LTDA | C29: SINERGIA ATACADISTA | D29: 08.298.936/0001-52 | E29: Vila Velha | F29: ES | G29: 1 | H29: XAVIER | I29: Sudeste | J29: Vendedor (alinhar antes) | K29: PV0003 - TABELA PADRÃO | L29: 46066 | M29: 46099 | N29: =TODAY()-M29 -> 223 | O29: 5213 | P29: 2 | Q29: =IF(P29>0,O29/P29,0) -> 2606.5 | R29: Frasqueiras 100% | S29: Só frasqueiras. | T29: A contatar
A30: =IF(O30>=20000,"A",IF(O30>=5000,"B","C")) -> C | B30: FEM DISTRIBUIDORA E IMPORTADORA LTDA | C30: FEM DISTRIBUIDORA | D30: 28.044.775/0001-88 | E30: Santos | F30: SP | G30: 1 | H30: AUTO ATEND. | I30: Coord. Int | J30: SDR (sem dono) | K30: PV0003 - TABELA PADRÃO | L30: 45629 | M30: 45629 | N30: =TODAY()-M30 -> 693 | O30: 4556 | P30: 1 | Q30: =IF(P30>0,O30/P30,0) -> 4556 | R30: Organização 100% | T30: A contatar
A31: =IF(O31>=20000,"A",IF(O31>=5000,"B","C")) -> C | B31: NT DISTRIBUICAO LTDA | C31: NT DISTRIBUICAO | D31: 38.485.048/0001-00 | E31: Nazaré Paulista | F31: SP | G31: 1 | H31: AUTO ATEND. | I31: Coord. Int | J31: SDR (sem dono) | K31: PV0004 - TABELA ESPECIAL RED | L31: 45889 | M31: 45889 | N31: =TODAY()-M31 -> 433 | O31: 3802 | P31: 1 | Q31: =IF(P31>0,O31/P31,0) -> 3802 | R31: Potes 94% | Organização 3% | Cozinha 3% | T31: A contatar
A32: =IF(O32>=20000,"A",IF(O32>=5000,"B","C")) -> C | B32: V R ESTRELA DISTRIBUIDORA DE UTILIDADES | C32: LOJA BELLATRIZ | D32: 37.268.552/0001-95 | E32: Vespasiano | F32: MG | G32: 1 | H32: EVERTON | I32: Sudeste | J32: Vendedor (alinhar antes) | K32: PV0003 - TABELA PADRÃO | L32: 45854 | M32: 45854 | N32: =TODAY()-M32 -> 468 | O32: 3487 | P32: 1 | Q32: =IF(P32>0,O32/P32,0) -> 3487 | R32: Cozinha 46% | Potes 16% | Banheiro 13% | T32: A contatar
A33: =IF(O33>=20000,"A",IF(O33>=5000,"B","C")) -> C | B33: MAX COMERCIO E DISTRIBUICAO DE ALIMENTOS | C33: MAX COMERCIO | D33: 04.516.447/0001-79 | E33: Vila Velha | F33: ES | G33: 1 | H33: AUTO ATEND. | I33: Coord. Int | J33: SDR (sem dono) | K33: PV0003 - TABELA PADRÃO | L33: 45621 | M33: 45646 | N33: =TODAY()-M33 -> 676 | O33: 3378 | P33: 2 | Q33: =IF(P33>0,O33/P33,0) -> 1689 | R33: Potes 54% | Jarras 11% | Lixeiras 11% | T33: A contatar
A34: =IF(O34>=20000,"A",IF(O34>=5000,"B","C")) -> C | B34: DATA DISTRIBUIDORA LTDA | C34: DATA DISTRIBUIDORA | D34: 54.322.975/0001-65 | E34: São Paulo | F34: SP | G34: 1 | H34: LUCIANA MITIE | I34: Capital SP | J34: Vendedor (alinhar antes) | K34: PV0003 - TABELA PADRÃO | L34: 45743 | M34: 45769 | N34: =TODAY()-M34 -> 553 | O34: 3362 | P34: 2 | Q34: =IF(P34>0,O34/P34,0) -> 1681 | R34: Teca Organização 24% | Potes 23% | ECO 18% | T34: A contatar
A35: =IF(O35>=20000,"A",IF(O35>=5000,"B","C")) -> C | B35: PACTO IMPORTADORA E DISTRIBUIDORA LTDA | C35: MVSTORE SHOP | D35: 49.166.985/0001-19 | E35: Itatiba | F35: SP | G35: 1 | H35: AUTO ATEND. | I35: Coord. Int | J35: SDR (sem dono) | K35: PV0003 - TABELA PADRÃO | L35: 45603 | M35: 45603 | N35: =TODAY()-M35 -> 719 | O35: 3358 | P35: 1 | Q35: =IF(P35>0,O35/P35,0) -> 3358 | R35: Organização 100% | T35: A contatar
A36: =IF(O36>=20000,"A",IF(O36>=5000,"B","C")) -> C | B36: FORMOSA DISTRIBUIDORA DE UTILIDADES DOMESTICAS - EIRELI | C36: FORMOSA DISTRIBUIDORA | D36: 16.798.922/0001-26 | E36: São Paulo | F36: SP | G36: 1 | H36: MAURO | I36: Capital SP | J36: Vendedor (alinhar antes) | K36: PV0003 - TABELA PADRÃO | L36: 45607 | M36: 45607 | N36: =TODAY()-M36 -> 715 | O36: 2819 | P36: 1 | Q36: =IF(P36>0,O36/P36,0) -> 2819 | R36: Cozinha 37% | Lixeiras 18% | Organização 16% | T36: A contatar
A37: =IF(O37>=20000,"A",IF(O37>=5000,"B","C")) -> C | B37: DISTRIBUIDORA DE UTILIDADES DOMESTICAS ROSSATO LTDA | C37: ROSSATO | D37: 17.060.355/0001-79 | E37: Guarulhos | F37: SP | G37: 1 | H37: MARCIO | I37: Grd SP e L | J37: Vendedor (alinhar antes) | K37: CLUBE NITRON RED 153 VAREJO COMISSÃO 8% | L37: 46204 | M37: 46204 | N37: =TODAY()-M37 -> 118 | O37: 2594 | P37: 3 | Q37: =IF(P37>0,O37/P37,0) -> 864.66667 | R37: Organização 30% | Decor-Confeitaria 27% | Lixeiras 14% | S37: 1ª compra jul/26 em tabela de varejo: avaliar tabela de distribuidor. | T37: A contatar
A38: =IF(O38>=20000,"A",IF(O38>=5000,"B","C")) -> C | B38: LOTUS CENTRAL DE DISTRIBUICAO DE HIGIENICOS LTDA | C38: SALES DISTRIBUIDORA | D38: 58.055.343/0001-33 | E38: São Paulo | F38: SP | G38: 1 | H38: MONICA | I38: Coord. Int | J38: Vendedor (alinhar antes) | K38: PV0003 - TABELA PADRÃO | L38: 46206 | M38: 46206 | N38: =TODAY()-M38 -> 116 | O38: 2551 | P38: 1 | Q38: =IF(P38>0,O38/P38,0) -> 2551 | R38: Frasqueiras 100% | S38: Distribuidora de higiene; 1ª compra jul/26 (só frasqueiras). Fazer a 2ª. | T38: A contatar
A39: =IF(O39>=20000,"A",IF(O39>=5000,"B","C")) -> C | B39: GECORE COMERCIAL DISTRIBUIDORA LTDA | C39: GECORE | D39: 27.238.815/0001-60 | E39: Vitória | F39: ES | G39: 1 | H39: JOANA | I39: Sudeste | J39: Vendedor (alinhar antes) | K39: PV0003 - TABELA PADRÃO | L39: 45768 | M39: 45768 | N39: =TODAY()-M39 -> 554 | O39: 2511 | P39: 1 | Q39: =IF(P39>0,O39/P39,0) -> 2511 | R39: Organização 77% | Frasqueiras 10% | Potes 7% | T39: A contatar
A40: =IF(O40>=20000,"A",IF(O40>=5000,"B","C")) -> C | B40: UD QUALITEC, DISTRIBUIDORA E SERVICOS LTDA | C40: QUALITEC | D40: 00.567.117/0001-51 | E40: São Paulo | F40: SP | G40: 1 | H40: AUTO ATEND. | I40: Coord. Int | J40: SDR (sem dono) | K40: PV0003 - TABELA PADRÃO | L40: 45607 | M40: 45607 | N40: =TODAY()-M40 -> 715 | O40: 1890 | P40: 1 | Q40: =IF(P40>0,O40/P40,0) -> 1890 | R40: Frasqueiras 33% | Banheiro 23% | Cozinha 17% | T40: A contatar
...

Sheet Lojas em tabela atacado
A1: Prioridade | B1: Razão social | C1: Nome fantasia | D1: CNPJ | E1: Cidade | F1: UF | G1: Lojas/CNPJs | H1: Vendedor da carteira | I1: Gestor | J1: Quem liga | K1: Tabela de preço | L1: 1ª compra | M1: Última compra | N1: Dias sem compra | O1: Faturamento 24m (R$) | P1: Notas 24m | Q1: Ticket médio (R$) | R1: Linhas que mais comprava | S1: Observação | T1: Status | U1: Data do contato | V1: Responsável | W1: Motivo da parada | X1: Próximo passo | Y1: Valor do pedido (R$)
A2: =IF(O2>=20000,"A",IF(O2>=5000,"B","C")) -> A | B2: COLATINA UTILIDADES EIRELI - EPP | C2: MEGALAR (rede 24 lojas) | D2: 11.293.416/0001-61 | E2: Colatina | F2: ES | G2: 24 | H2: JOANA | I2: MARCOS | J2: Vendedor (alinhar antes) | K2: TABELA MEGALAR CLUBE ATACADO CIF | L2: 45687 | M2: 46255 | N2: =TODAY()-M2 -> 67 | O2: 302650 | P2: 83 | Q2: =IF(P2>0,O2/P2,0) -> 3646.3855 | R2: Organização 32% | Lixeiras 15% | Cozinha 13% | S2: Rede de 24 lojas sem key account: avaliar se vira KA. | T2: A contatar
A3: =IF(O3>=20000,"A",IF(O3>=5000,"B","C")) -> A | B3: ACHEI ATACAREJO DO PUTIM LTDA | C3: ACHEI ATACAREJO (rede 10 lojas) | D3: 48.378.994/0001-00 | E3: São José dos Campos | F3: SP | G3: 10 | H3: ROBERTO | I3: Int e Vale | J3: Vendedor (alinhar antes) | K3: PV0003 - TABELA PADRÃO | L3: 45628 | M3: 46255 | N3: =TODAY()-M3 -> 67 | O3: 80429 | P3: 25 | Q3: =IF(P3>0,O3/P3,0) -> 3217.16 | R3: Organização 44% | Potes 20% | Cozinha 8% | S3: Atacarejo com 10 lojas. | T3: A contatar
A4: =IF(O4>=20000,"A",IF(O4>=5000,"B","C")) -> A | B4: ESTILO TOP ONLINE LTDA | C4: ESTILO TOP ONLINE | D4: 51.959.734/0001-33 | E4: São Bernardo do Campo | F4: SP | G4: 1 | H4: EDSON GRAVINEZ | I4: MARCOS | J4: Vendedor (alinhar antes) | K4: CLUBE NITRON ATACADO COMISSÃO 6% | L4: 45693 | M4: 46146 | N4: =TODAY()-M4 -> 176 | O4: 52772 | P4: 5 | Q4: =IF(P4>0,O4/P4,0) -> 10554.4 | R4: Frasqueiras 37% | Micro-ondas 31% | Cozinha 19% | S4: Revenda online. | T4: A contatar
A5: =IF(O5>=20000,"A",IF(O5>=5000,"B","C")) -> A | B5: R NICOLETTI COMERCIO DE UTD DOMESTICAS | C5: MUNDO UD | D5: 41.297.731/0001-28 | E5: São Paulo | F5: SP | G5: 2 | H5: AUTO ATEND. | I5: Coord. Int | J5: SDR (sem dono) | K5: PREÇO DE CUSTO INICIAL | L5: 45593 | M5: 45897 | N5: =TODAY()-M5 -> 425 | O5: 48710 | P5: 108 | Q5: =IF(P5>0,O5/P5,0) -> 451.01852 | R5: Potes 41% | Organização 14% | Lixeiras 9% | S5: 108 notas pequenas: provável revenda online. | T5: A contatar
A6: =IF(O6>=20000,"A",IF(O6>=5000,"B","C")) -> A | B6: 52.888.479 ALINE DAIANE DOS SANTOS BUOSI | C6: ALINE DAIANE (MEI) | D6: 52.888.479/0001-48 | E6: Mogi das Cruzes | F6: SP | G6: 1 | H6: MONICA | I6: Coord. Int | J6: Vendedor (alinhar antes) | K6: CLUBE NITRON RED 155 ATACAD. COMISSÃO 6% | L6: 45854 | M6: 46237 | N6: =TODAY()-M6 -> 85 | O6: 29276 | P6: 16 | Q6: =IF(P6>0,O6/P6,0) -> 1829.75 | R6: Frasqueiras 43% | Potes 32% | Micro-ondas 8% | S6: MEI revendedora, compra frequente. | T6: A contatar
A7: =IF(O7>=20000,"A",IF(O7>=5000,"B","C")) -> A | B7: MANIA DO LAR COMERCIO DE UTILIDADES LTDA | C7: MANIA DO LAR | D7: 16.859.112/0001-32 | E7: Sertãozinho | F7: SP | G7: 1 | H7: SEBASTIAO | I7: Int e Vale | J7: Vendedor (alinhar antes) | K7: CLUBE NITRON ATACADO COMISSÃO 6% | L7: 45716 | M7: 46170 | N7: =TODAY()-M7 -> 152 | O7: 28723 | P7: 7 | Q7: =IF(P7>0,O7/P7,0) -> 4103.2857 | R7: Organização 37% | Potes 17% | Cozinha 9% | T7: A contatar
A8: =IF(O8>=20000,"A",IF(O8>=5000,"B","C")) -> A | B8: ENOKI PRESENTES BRINQUEDOS E UTILIDADES LTDA | C8: ENOKI | D8: 35.300.857/0001-01 | E8: Jaboticabal | F8: SP | G8: 1 | H8: SEBASTIAO | I8: Int e Vale | J8: Vendedor (alinhar antes) | K8: CLUBE NITRON ATACADO COMISSÃO 6% | L8: 45602 | M8: 45929 | N8: =TODAY()-M8 -> 393 | O8: 28666 | P8: 4 | Q8: =IF(P8>0,O8/P8,0) -> 7166.5 | R8: Organização 38% | Potes 14% | Lixeiras 13% | S8: Mesma família da Enokis (Jaboticabal). | T8: A contatar
A9: =IF(O9>=20000,"A",IF(O9>=5000,"B","C")) -> A | B9: P.V.E. COMERCIO DE UTENSILIOS PARA O LAR | C9: PVE UTENSILIOS | D9: 10.571.938/0001-15 | E9: Resende | F9: RJ | G9: 1 | H9: OSWALDO | I9: Capital SP | J9: Vendedor (alinhar antes) | K9: CLUBE NITRON ATACADO COMISSÃO 6% | L9: 45796 | M9: 46118 | N9: =TODAY()-M9 -> 204 | O9: 22553 | P9: 3 | Q9: =IF(P9>0,O9/P9,0) -> 7517.6667 | R9: Organização 32% | Cozinha 24% | Lixeiras 16% | T9: A contatar
A10: =IF(O10>=20000,"A",IF(O10>=5000,"B","C")) -> A | B10: TERESA TANAKA LTDA | C10: REDE BRINK E LAR | D10: 05.260.418/0001-51 | E10: Presidente Epitácio | F10: SP | G10: 1 | H10: JOSÉ FERNANDO | I10: Int e Vale | J10: Vendedor (alinhar antes) | K10: CLUBE NITRON ATACADO COMISSÃO 6% | L10: 45838 | M10: 46123 | N10: =TODAY()-M10 -> 199 | O10: 20598 | P10: 3 | Q10: =IF(P10>0,O10/P10,0) -> 6866 | R10: Potes 27% | Organização 27% | Cozinha 19% | T10: A contatar
A11: =IF(O11>=20000,"A",IF(O11>=5000,"B","C")) -> A | B11: ENOKIS PRESENTES E BRINQUEDOS LTDA - ME | C11: ENOKIS | D11: 07.008.114/0001-27 | E11: Jaboticabal | F11: SP | G11: 1 | H11: SEBASTIAO | I11: Int e Vale | J11: Vendedor (alinhar antes) | K11: CLUBE NITRON ATACADO COMISSÃO 6% | L11: 45623 | M11: 46196 | N11: =TODAY()-M11 -> 126 | O11: 20536 | P11: 4 | Q11: =IF(P11>0,O11/P11,0) -> 5134 | R11: Potes 42% | Cozinha 27% | Organização 11% | S11: Mesma família da Enoki (Jaboticabal). | T11: A contatar
A12: =IF(O12>=20000,"A",IF(O12>=5000,"B","C")) -> A | B12: A. & I. UTILIDADES DO LAR LTDA. | C12: A PREFERIDA DO LAR | D12: 04.809.615/0001-14 | E12: Macaé | F12: RJ | G12: 1 | H12: OSWALDO | I12: Sudeste | J12: Vendedor (alinhar antes) | K12: CLUBE NITRON ATACADO COMISSÃO 6% | L12: 45622 | M12: 46221 | N12: =TODAY()-M12 -> 101 | O12: 20093 | P12: 4 | Q12: =IF(P12>0,O12/P12,0) -> 5023.25 | R12: Organização 25% | Cozinha 13% | Frasqueiras 12% | T12: A contatar
A13: =IF(O13>=20000,"A",IF(O13>=5000,"B","C")) -> B | B13: MILTON JOSE NONATO MARQUES ME | C13: LOJAO DO 9 | D13: 19.634.713/0001-35 | E13: Teodoro Sampaio | F13: SP | G13: 1 | H13: JOSÉ FERNANDO | I13: Int e Vale | J13: Vendedor (alinhar antes) | K13: CLUBE NITRON RED 155 ATACAD. COMISSÃO 6% | L13: 45604 | M13: 46248 | N13: =TODAY()-M13 -> 74 | O13: 19587 | P13: 4 | Q13: =IF(P13>0,O13/P13,0) -> 4896.75 | R13: Cozinha 31% | Potes 28% | Organização 11% | T13: A contatar
A14: =IF(O14>=20000,"A",IF(O14>=5000,"B","C")) -> B | B14: FLAVIO G. DUARTE JUNIOR | C14: FLAVIO DUARTE | D14: 17.982.808/0004-67 | E14: Serra | F14: ES | G14: 1 | H14: JOANA | I14: Sudeste | J14: Vendedor (alinhar antes) | K14: CLUBE NITRON ATACADO COMISSÃO 6% | L14: 46248 | M14: 46248 | N14: =TODAY()-M14 -> 74 | O14: 6888 | P14: 1 | Q14: =IF(P14>0,O14/P14,0) -> 6888 | R14: Potes 38% | Cozinha 28% | Organização 15% | T14: A contatar
A15: =IF(O15>=20000,"A",IF(O15>=5000,"B","C")) -> B | B15: PEDRO CESAR DA SILVA 01329436628 | C15: 180 GRAUS | D15: 40.858.075/0001-22 | E15: Patos de Minas | F15: MG | G15: 2 | H15: GERALDO | I15: Sudeste | J15: Vendedor (alinhar antes) | K15: PV0003 - TABELA PADRÃO | L15: 45754 | M15: 46155 | N15: =TODAY()-M15 -> 167 | O15: 6037 | P15: 2 | Q15: =IF(P15>0,O15/P15,0) -> 3018.5 | R15: Potes 28% | Cozinha 21% | Banheiro 18% | T15: A contatar

Sheet Key accounts (gestor)
A1: Grupo | B1: Key account | C1: Lojas | D1: UF | E1: Vendedor | F1: Gestor | G1: Última compra do grupo | H1: Dias sem compra | I1: Faturamento 24m (R$) | J1: Notas 24m | K1: Leitura
A2: LOJAS G (PAF UTILIDADES E PRESENTES) | B2: LOJA G | C2: 78 | D2: SP/MG/RJ | E2: JOÃO CARLOS | F2: RICARDO | G2: 46262 | H2: =TODAY()-G2 -> 60 | I2: 3091888 | J2: 496 | K2: 60 dias sem pedido no grupo: pode ser só o ciclo, mas é o maior volume da lista. Conferir com o gestor.
A3: TUBARÃO (MULTI ATACADO / HOMELAR / COMPAG) | B3: TUBARÃO | C3: 30 | D3: RJ/MG | E3: MILTON | F3: RICARDO | G3: 46203 | H3: =TODAY()-G3 -> 119 | I3: 1873559 | J3: 128 | K3: Parou depois de 30/06 em todas as lojas: queda de rede inteira, conversa de diretoria.
A4: ATACADÃO (WMS SUPERMERCADOS) | B4: ATACADAO | C4: 68 | D4: SP | E4: JULIO SANCHEZ | F4: RICARDO | G4: 45817 | H4: =TODAY()-G4 -> 505 | I4: 296204 | J4: 68 | K4: Comprou uma vez (jun/25, 68 lojas) e não repetiu.
A5: ROYAL MAGAZINE (R Y COSMÉTICOS) | B5: ROYAL MAGAZINE | C5: 4 | D5: SP | E5: EDSON GRAVINEZ | F5: MARCOS | G5: 46162 | H5: =TODAY()-G5 -> 160 | I5: 228650 | J5: 17 | K5: Parado desde mai/26.
A6: LOJAS G - ARAXÁ (CE & CP) | B6: LOJA G | C6: 1 | D6: MG | E6: JOÃO CARLOS | F6: Sudeste | G6: 46258 | H6: =TODAY()-G6 -> 64 | I6: 55165 | J6: 5 | K6: Mesma bandeira Lojas G.
A7: G20 IMPORTAÇÃO (GR IMPORTADOS / PIABETA) | B7: G20 IMPORTACAO | C7: 2 | D7: RJ | E7: TIAGO SANTOS | F7: Sudeste | G7: 45713 | H7: =TODAY()-G7 -> 609 | I7: 46542 | J7: 2 | K7: Comprou 2 vezes em fev/25.
A8: NEW PAPER (BAZAR OPÇÃO) | B8: NEW PAPER | C8: 1 | D8: RJ | E8: LUCIANE VOGEL | F8: MARCOS | G8: 46245 | H8: =TODAY()-G8 -> 77 | I8: 40168 | J8: 2 | K8: Cliente novo (mar/26), 2 pedidos.
A9: LOJAS G - BAURU (PAF) | B9: LOJA G | C9: 1 | D9: SP | E9: JOÃO CARLOS | F9: Int e Vale | G9: 46258 | H9: =TODAY()-G9 -> 64 | I9: 27930 | J9: 3 | K9: Mesma bandeira Lojas G.

Sheet Fora da lista
A1: Empresa | B1: Cidade/UF | C1: Por que saiu | D1: Faturamento 24m (R$)
A2: DIMESO S.A. | B2: Sorocaba/SP | C2: Distribuidora médico-hospitalar (fora do segmento) | D2: 45810
A3: FERNANDES DISTRIBUIDORA DE PEÇAS ELÉTRICAS AUTOMOTIVAS | B3: Barueri/SP | C3: Autopeças (fora do segmento) | D3: 8802
A4: RIO PRETO DISTRIBUIDORA DE VEDAÇÕES | B4: S. J. Rio Preto/SP | C4: Vedações industriais (fora do segmento) | D4: 2592
A5: ABS DISTRIBUIDORA - filial Mococa | B5: Mococa/SP | C5: Grupo Palmares segue comprando pela filial de Passos/MG | D5: 119120
A6: RIO CENTER DISTRIBUIDORA / OBA RIO | B6: Rio de Janeiro/RJ | C6: Grupo Amigão comprou nos últimos 60 dias: tratar com o key account | D6: 1330662
A7: Compras < R$ 1.500 em 24 meses (farmácia, livros, bebidas, hortifrúti etc.) | B7: diversas | C7: Pedido avulso de site, não é distribuidor | D7: 0
